<?xml version="1.0" encoding="utf-8"?>
<!-- This URDF was automatically created by SolidWorks to URDF Exporter! Originally created by Stephen Brawner (brawner@gmail.com) 
     Commit Version: 1.6.0-4-g7f85cfe  Build Version: 1.6.7995.38578
     For more information, please see http://wiki.ros.org/sw_urdf_exporter -->
<robot
  name="myrobot">
  <!-- BASE_LINK -->
  <link
    name="base_link">
    <inertial>
      <origin
        xyz="0.0021672 5.2269E-05 0.075206"
        rpy="0 0 0" />
      <mass
        value="0.94224" />
      <inertia
        ixx="0.0021709"
        ixy="4.448E-06"
        ixz="-9.7494E-05"
        iyy="0.0029755"
        iyz="-5.8642E-06"
        izz="0.0042219" />
    </inertial>
    <visual>
      <origin
        xyz="0 0 0"
        rpy="0 0 0" />
      <geometry>
        <mesh
          filename="package://myrobot/meshes/base_link.STL" />
      </geometry>
      <material
        name="">
        <color
          rgba="0.79216 0.81961 0.93333 1" />
      </material>
    </visual>
    <collision>
      <origin
        xyz="0 0 0"
        rpy="0 0 0" />
      <geometry>
        <mesh
          filename="package://myrobot/meshes/base_link.STL" />
      </geometry>
    </collision>

    <!-- CAMERA_LINK -->
  </link>
  <link
    name="camera_link">
    <inertial>
      <origin
        xyz="-0.0091066 -3.1937E-05 0.0028313"
        rpy="0 0 0" />
      <mass
        value="0.0015485" />
      <inertia
        ixx="9.8143E-08"
        ixy="1.5504E-11"
        ixz="2.7478E-09"
        iyy="6.1527E-08"
        iyz="3.7675E-10"
        izz="5.633E-08" />
    </inertial>
    <visual>
      <origin
        xyz="0 0 0"
        rpy="0 0 0" />
      <geometry>
        <mesh
          filename="package://myrobot/meshes/camera_link.STL" />
      </geometry>
      <material
        name="">
        <color
          rgba="0.79216 0.81961 0.93333 1" />
      </material>
    </visual>
    <collision>
      <origin
        xyz="0 0 0"
        rpy="0 0 0" />
      <geometry>
        <mesh
          filename="package://myrobot/meshes/camera_link.STL" />
      </geometry>
    </collision>
  </link>
  <joint
    name="camera_joint"
    type="fixed">
    <origin
      xyz="0.129 -7.197E-05 0.12332"
      rpy="0 0 0" />
    <parent
      link="base_link" />
    <child
      link="camera_link" />
    <axis
      xyz="0 0 0" />
  </joint>

  <!-- HOAT DONG CAMERA TREN GAZEBO -->
  <gazebo reference="camera_link">
    <sensor type="camera" name="camera_sensor">
      <update_rate>30</update_rate>
      <camera>
        <horizontal_fov>1.39626</horizontal_fov>
        <image>
          <width>320</width>
          <height>240</height>
          <format>R8G8B8</format>
        </image>
      </camera>
      <plugin name="camera_controller" filename="libgazebo_ros_camera.so">
        <alwaysOn>true</alwaysOn>
        <updateRate>30</updateRate>
        <cameraName>myrobot_camera</cameraName>
        <imageTopicName>/camera/image_raw</imageTopicName>
        <cameraInfoTopicName>/camera/camera_info</cameraInfoTopicName>
        <frameName>camera_link</frameName>
      </plugin>
    </sensor>
    <origin xyz="0.129 -7.197E-05 0.12332"
      rpy="0 0 0"/> 
  </gazebo>
  
  <!-- IMU_LINK -->
  <link
    name="imu_link">
    <inertial>
      <origin
        xyz="0.010453 -0.048916 -0.0010078"
        rpy="0 0 0" />
      <mass
        value="0.00054834" />
      <inertia
        ixx="8.6844E-09"
        ixy="-3.334E-11"
        ixz="-4.4417E-11"
        iyy="1.9444E-08"
        iyz="8.0656E-11"
        izz="2.6482E-08" />
    </inertial>
    <visual>
      <origin
        xyz="0 0 0"
        rpy="0 0 0" />
      <geometry>
        <mesh
          filename="package://myrobot/meshes/imu_link.STL" />
      </geometry>
      <material
        name="">
        <color
          rgba="0.79216 0.81961 0.93333 1" />
      </material>
    </visual>
    <collision>
      <origin
        xyz="0 0 0"
        rpy="0 0 0" />
      <geometry>
        <mesh
          filename="package://myrobot/meshes/imu_link.STL" />
      </geometry>
    </collision>
  </link>
  <joint
    name="imu_joint"
    type="fixed">
    <origin
      xyz="0.083172 0.050916 0.067856"
      rpy="0 0 0" />
    <parent
      link="base_link" />
    <child
      link="imu_link" />
    <axis
      xyz="0 0 0" />
  </joint>
  <!-- HOAT DONG IMU TREN GAZEBO -->
  <gazebo reference="imu_link">
    <sensor type="imu" name="imu_sensor">
      <updateRateHZ>50</updateRateHZ>
      <plugin name="imu_plugin" filename="libgazebo_ros_imu_sensor.so">
        <alwaysOn>true</alwaysOn>
        <updateRateHZ>50</updateRateHZ>
        <gaussianNoise>0.01</gaussianNoise>
         <xyzOffset>0 0 0</xyzOffset>
         <rpyOffset>0 0 0</rpyOffset>
        <topicName>/imu/data</topicName>
        <frameName>imu_link</frameName>
      </plugin>
    </sensor>
  </gazebo>
  
  <!-- LIDAR_LINK -->
  <link
    name="lidar_link">
    <inertial>
      <origin
        xyz="0.011787 -0.00029728 -0.035501"
        rpy="0 0 0" />
      <mass
        value="0.094104" />
      <inertia
        ixx="2.791E-05"
        ixy="-1.2576E-07"
        ixz="-3.3545E-07"
        iyy="4.4352E-05"
        iyz="2.3376E-08"
        izz="6.9475E-05" />
    </inertial>
    <visual>
      <origin
        xyz="0 0 0"
        rpy="0 0 0" />
      <geometry>
        <mesh
          filename="package://myrobot/meshes/lidar_link.STL" />
      </geometry>
      <material
        name="">
        <color
          rgba="0.79216 0.81961 0.93333 1" />
      </material>
    </visual>
    <collision>
      <origin
        xyz="0 0 0"
        rpy="0 0 0" />
      <geometry>
        <mesh
          filename="package://myrobot/meshes/lidar_link.STL" />
      </geometry>
    </collision>
  </link>
  <joint
    name="lidar_joint"
    type="fixed">
    <origin
      xyz="0.049018 -0.00031196 0.17124"
      rpy="0 0 0" />
    <parent
      link="base_link" />
    <child
      link="lidar_link" />
    <axis
      xyz="0 0 0" />
  </joint>

  <!-- HOAT DONG LIDAR TREN GAZEBO-->
  <gazebo reference="lidar_link">
    <sensor type="ray" name="lidar_sensor">
      <update_rate>10</update_rate>
      <ray>
        <scan>
          <horizontal>
            <samples>360</samples>
            <resolution>1.0</resolution>
            <min_angle>-1.57</min_angle>
            <max_angle>1.57</max_angle>
          </horizontal>
        </scan>
        <range>
          <min>0.1</min>
          <max>10.0</max>
          <resolution>0.01</resolution>
        </range>
      </ray>
      <plugin name="lidar_plugin" filename="libgazebo_ros_laser.so">
        <alwaysOn>true</alwaysOn>
        <updateRate>10</updateRate>
        <topicName>/scan</topicName>
        <frameName>lidar_link</frameName>
      </plugin>
    </sensor>
  </gazebo>
  
  <!-- MOTOR -->
  <link
    name="motor_left_link">
    <inertial>
      <origin
        xyz="-1.002E-05 0.017054 4.0634E-06"
        rpy="0 0 0" />
      <mass
        value="0.01319" />
      <inertia
        ixx="2.7998E-06"
        ixy="-1.3699E-09"
        ixz="2.0596E-09"
        iyy="3.1329E-06"
        iyz="5.5346E-10"
        izz="2.8041E-06" />
    </inertial>
    <visual>
      <origin
        xyz="0 0 0"
        rpy="0 0 0" />
      <geometry>
        <mesh
          filename="package://myrobot/meshes/motor_left_link.STL" />
      </geometry>
      <material
        name="">
        <color
          rgba="0.79216 0.81961 0.93333 1" />
      </material>
    </visual>
    <collision>
      <origin
        xyz="0 0 0"
        rpy="0 0 0" />
      <geometry>
       <mesh
          filename="package://myrobot/meshes/motor_left_link.STL" />
      </geometry>
    </collision>
  </link>
  <joint
    name="motor_left_joint"
    type="continuous">
    <origin
      xyz="-0.0549 0.05298 0.026106"
      rpy="0 0 0" />
    <parent
      link="base_link" />
    <child
      link="motor_left_link" />
    <axis
      xyz="0 1 0" />
    <limit effort="100" velocity="10" lower="-2.0" upper="2.0"/>
</joint>
  <link
    name="motor_right_link">
    <inertial>
      <origin
        xyz="-0.00036227 -0.017082 -7.7231E-07"
        rpy="0 0 0" />
      <mass
        value="0.01319" />
      <inertia
        ixx="2.7992E-06"
        ixy="8.3384E-09"
        ixz="-4.1884E-10"
        iyy="3.1326E-06"
        iyz="1.1227E-10"
        izz="2.8049E-06" />
    </inertial>
    <visual>
      <origin
        xyz="0 0 0"
        rpy="0 0 0" />
      <geometry>
        <mesh
          filename="package://myrobot/meshes/motor_right_link.STL" />
      </geometry>
      <material
        name="">
        <color
          rgba="0.79216 0.81961 0.93333 1" />
      </material>
    </visual>
    <collision>
      <origin
        xyz="0 0 0"
        rpy="0 0 0" />
      <geometry>
        <mesh
          filename="package://myrobot/meshes/motor_right_link.STL" />
        </geometry>
    </collision>
  </link>
  <joint
    name="motor_right_joint"
    type="continuous">
    <origin
      xyz="0.0549001025253852 -0.0529484297194092 0.0261064627897476"
      rpy="0 0 0.0205732401062777" />
    <parent
      link="base_link" />
    <child
      link="motor_right_link" />
    <axis
      xyz="0.0205717888382007 0.999788378360139 0" />
    <limit effort="100" velocity="10" lower="-2.0" upper="2.0"/>
</joint>

<!-- ARM -->
   <link name="arm_base_link">
    <inertial>
      <origin
        xyz="0.00075864 -5.7988E-06 0.0069673"
        rpy="0 0 0" />
      <mass
        value="0.027" />
      <inertia
        ixx="1.317E-05"
        ixy="-1.0851E-10"
        ixz="2.7024E-08"
        iyy="1.3156E-05"
        iyz="-2.0657E-10"
        izz="1.8425E-05" />
    </inertial>
    <visual>
      <origin
        xyz="0 0 0"
        rpy="0 0 0" />
      <geometry>
        <mesh
          filename="package://myrobot/meshes/arm_base_link.STL" />
      </geometry>
      <material
        name="">
        <color
          rgba="0.79216 0.81961 0.93333 1" />
      </material>
    </visual>
    <collision>
      <origin
        xyz="0 0 0"
        rpy="0 0 0" />
      <geometry>
        <mesh
          filename="package://myrobot/meshes/arm_base_link.STL" />
      </geometry>
    </collision>
  </link>
  <joint
    name="arm_base_joint"
    type="fixed">
    <origin
      xyz="-0.034782 0.00033271 0.16142"
      rpy="0 0 -3.121" />
    <parent
      link="base_link" />
    <child
      link="arm_base_link" />
    <axis
      xyz="0 0 0" />
  </joint>
  <link
    name="arm_joint1_link">
    <inertial>
      <origin
        xyz="0.042921 0.00034486 0.023448"
        rpy="0 0 0" />
      <mass
        value="0.037293" />
      <inertia
        ixx="4.9272E-06"
        ixy="-2.0557E-07"
        ixz="-1.0955E-06"
        iyy="1.135E-05"
        iyz="-1.2841E-07"
        izz="1.203E-05" />
    </inertial>
    <visual>
      <origin
        xyz="0 0 0"
        rpy="0 0 0" />
      <geometry>
        <mesh
          filename="package://myrobot/meshes/arm_joint1_link.STL" />
      </geometry>
      <material
        name="">
        <color
          rgba="0.79216 0.81961 0.93333 1" />
      </material>
    </visual>
    <collision>
      <origin
        xyz="0 0 0"
        rpy="0 0 0" />
      <geometry>
        <mesh
          filename="package://myrobot/meshes/arm_joint1_link.STL" />
      </geometry>
    </collision>
  </link>
  <joint
    name="arm_joint1_joint"
    type="revolute">
    <origin
      xyz="0.00020933874096328 0 0.0339940637763312"
      rpy="0 0 3.13784873119313" />
    <parent
      link="arm_base_link" />
    <child
      link="arm_joint1_link" />
    <axis
      xyz="0 0 1" />
    <limit lower="-1.57" upper="1.57" effort="5" velocity="1.5" />
  </joint>
  <link
    name="arm_joint2_link">
    <inertial>
      <origin
        xyz="0.044847 0.00089754 1.2383E-09"
        rpy="0 0 0" />
      <mass
        value="0.0031326" />
      <inertia
        ixx="4.0312E-08"
        ixy="1.3464E-09"
        ixz="-7.6073E-13"
        iyy="6.7739E-07"
        iyz="1.1969E-13"
        izz="6.841E-07" />
    </inertial>
    <visual>
      <origin
        xyz="0 0 0"
        rpy="0 0 0" />
      <geometry>
        <mesh
          filename="package://myrobot/meshes/arm_joint2_link.STL" />
      </geometry>
      <material
        name="">
        <color
          rgba="0.79216 0.81961 0.93333 1" />
      </material>
    </visual>
    <collision>
      <origin
        xyz="0 0 0"
        rpy="0 0 0" />
      <geometry>
        <mesh
          filename="package://myrobot/meshes/arm_joint2_link.STL" />
      </geometry>
    </collision>
  </link>
  <joint
    name="arm_joint2_joint"
    type="prismatic">
    <origin
      xyz="0.0833 -0.00019994 0.041773"
      rpy="0 0 0" />
    <parent
      link="arm_joint1_link" />
    <child
      link="arm_joint2_link" />
    <axis
      xyz="-1 0 0" />
    <limit lower="-0.1" upper="0.1" effort="5" velocity="1" />
  </joint>

<!-- DIEU KHIEN BANH XE -->
<!-- Transmission -->
<transmission name="motor_left_trans">
  <type>transmission_interface/SimpleTransmission</type>
  <joint name="motor_left_joint">
    <hardwareInterface>hardware_interface/VelocityJointInterface</hardwareInterface>
  </joint>
  <actuator name="motor_left_actuator">
    <mechanicalReduction>10.0</mechanicalReduction>
    <hardwareInterface>hardware_interface/VelocityJointInterface</hardwareInterface>
  </actuator>
</transmission>

<transmission name="motor_right_trans">
  <type>transmission_interface/SimpleTransmission</type>
  <joint name="motor_right_joint">
    <hardwareInterface>hardware_interface/VelocityJointInterface</hardwareInterface>
  </joint>
  <actuator name="motor_right_actuator">
    <mechanicalReduction>10.0</mechanicalReduction>
    <hardwareInterface>hardware_interface/VelocityJointInterface</hardwareInterface>
  </actuator>
</transmission>
<!-- Plugin -->
<gazebo>
  <plugin name="gazebo_ros_control" filename="libgazebo_ros_control.so"/>
</gazebo>

<!-- DIEU KHIEN ARM -->
<!-- Transmission -->
  <transmission name="arm_joint1_joint_trans">
    <type>transmission_interface/SimpleTransmission</type>
    <joint name="arm_joint1_joint">
      <hardwareInterface>hardware_interface/PositionJointInterface</hardwareInterface>
    </joint>
    <actuator name="arm_joint1_joint_actuator">
      <mechanicalReduction>10.0</mechanicalReduction>
      <hardwareInterface>hardware_interface/PositionJointInterface</hardwareInterface>
    </actuator>
  </transmission>
  <transmission name="arm_joint2_joint_trans">
    <type>transmission_interface/SimpleTransmission</type>
    <joint name="arm_joint2_joint">
      <hardwareInterface>hardware_interface/PositionJointInterface</hardwareInterface>
          </joint>
    <actuator name="arm_joint2_joint_acutuator">
      <mechanicalReduction>10.0</mechanicalReduction>
      <hardwareInterface>hardware_interface/PositionJointInterface</hardwareInterface>
    </actuator>
  </transmission>
  <!-- Plugin -->
<plugin name="arm_control" filename="libgazebo_ros_control.so">
        <robotNamespace>/</robotNamespace>
    </plugin>
</robot>